func send(job: Int, toPrinter printerName: String) throws -> String {
    if printerName == "Never Has Toner" {
        throw PrinterError.noToner
    }
    return "Job sent"
}

do {
    let printerResponse = try send(job: 1440, toPrinter: "Gutenberg")
    print(printerResponse)
} catch PrinterError.onFire {
    print("I'll just put this over here, with the rest of the fire.")
} catch let printerError as PrinterError {
    print("Printer error: \(printerError).")
} catch {
    print(error)
}


另一种处理错误的方式使用 try? 将结果转换为可选的。如果函数抛出错误，该错误会被抛弃并且结果为 nil。否则的话，结果会是一个包含函数返回值的可选值。
let printerSuccess = try? send(job: 1884, toPrinter: "Mergenthaler")


使用 defer 代码块来表示在函数返回前，函数中最后执行的代码。无论函数是否会抛出错误，这段代码都将执行。使用 defer，可以把函数调用之初就要执行的代码和函数调用结束时的扫尾代码写在一起，虽然这两者的执行时机截然不同。
var fridgeIsOpen = false
let fridgeContent = ["milk", "eggs", "leftovers"]

func fridgeContains(_ food: String) -> Bool {
    fridgeIsOpen = true
    defer {
        fridgeIsOpen = false
    }

    let result = fridgeContent.contains(food)
    return result
}
fridgeContains("banana")
print(fridgeIsOpen)